2025-03-31 17:27:50,519 INFO [server.py:341] server listening on 0.0.0.0:10007
2025-03-31 17:27:54,178 INFO [server.py:529] connection open
2025-03-31 17:27:54,179 INFO [test2.py:270] Connected: ('10.109.246.210', 37160). Number of connections: 0/20
2025-03-31 17:30:38,116 INFO [test2.py:254] Disconnected: ('10.109.246.210', 37160). Number of connections: -1/20
2025-03-31 17:30:38,116 ERROR [server.py:378] connection handler failed
Traceback (most recent call last):
  File "/home/zdg/.conda/envs/sherpa-onnx/lib/python3.10/site-packages/websockets/asyncio/server.py", line 376, in conn_handler
    await self.handler(connection)
  File "/data/zdg/sherpa-onnx/test2.py", line 247, in handle_connection
    await self.handle_connection_impl(socket)
  File "/data/zdg/sherpa-onnx/test2.py", line 295, in handle_connection_impl
    samples = await self.recv_audio_samples(socket)
  File "/data/zdg/sherpa-onnx/test2.py", line 349, in recv_audio_samples
    message = await socket.recv()
  File "/home/zdg/.conda/envs/sherpa-onnx/lib/python3.10/site-packages/websockets/asyncio/connection.py", line 322, in recv
    raise self.protocol.close_exc from self.recv_exc
websockets.exceptions.ConnectionClosedOK: received 1000 (OK); then sent 1000 (OK)
2025-03-31 17:30:41,417 INFO [server.py:529] connection open
2025-03-31 17:30:41,418 INFO [test2.py:270] Connected: ('10.109.246.210', 60252). Number of connections: -1/20
2025-03-31 17:32:48,038 INFO [test2.py:254] Disconnected: ('10.109.246.210', 60252). Number of connections: -2/20
2025-03-31 17:32:48,039 INFO [server.py:440] server closing
2025-03-31 17:32:48,039 INFO [server.py:473] server closed
